<?xml version="1.0" ?>
<!-- =================================================================================== -->
<!-- |    This document was autogenerated by xacro from /root/ros1_ws/src/abb_ros1/abb_irb1300_support/urdf/irb1300.xacro | -->
<!-- |    EDITING THIS FILE BY HAND IS NOT RECOMMENDED                                 | -->
<!-- =================================================================================== -->
<robot name="abb_irb1300">
    <!-- Conversion were obtained from http://www.e-paint.co.uk/Lab_values.asp
       unless otherwise stated. -->
    <!-- link list -->
    <link name="base_link">
        <collision>
            <geometry>
                <mesh filename="package://abb_irb1300_support/meshes/collision/base_link.STL" />
            </geometry>
        </collision>
        <visual>
            <geometry>
                <mesh filename="package://abb_irb1300_support/meshes/visual/base_link.STL" />
            </geometry>
            <material name="">
                <color rgba="0.3450980 0.3647059 0.3686275 1" />
            </material>
        </visual>
        <inertial>
            <mass value="0.1" />
            <origin xyz="0 0 0" rpy="0 0 0" />
            <inertia ixx="0.03" iyy="0.03" izz="0.03" ixy="0.0" ixz="0.0" iyz="0.0" />
        </inertial>
    </link>
    <link name="link_1">
        <collision>
            <geometry>
                <mesh filename="package://abb_irb1300_support/meshes/collision/link_1.STL" />
            </geometry>
        </collision>
        <visual>
            <geometry>
                <mesh filename="package://abb_irb1300_support/meshes/visual/link_1.STL" />
            </geometry>
            <material name="">
                <color rgba="0.3450980 0.3647059 0.3686275 1" />
            </material>
        </visual>
        <inertial>
            <mass value="0.1" />
            <origin xyz="0 0 0" rpy="0 0 0" />
            <inertia ixx="0.03" iyy="0.03" izz="0.03" ixy="0.0" ixz="0.0" iyz="0.0" />
        </inertial>
    </link>
    <link name="link_2">
        <collision>
            <geometry>
                <mesh filename="package://abb_irb1300_support/meshes/collision/link_2.STL" />
            </geometry>
        </collision>
        <visual>
            <geometry>
                <mesh filename="package://abb_irb1300_support/meshes/visual/link_2.STL" />
            </geometry>
            <material name="">
                <color rgba="0.3450980 0.3647059 0.3686275 1" />
            </material>
        </visual>
        <inertial>
            <mass value="0.1" />
            <origin xyz="0 0 0" rpy="0 0 0" />
            <inertia ixx="0.03" iyy="0.03" izz="0.03" ixy="0.0" ixz="0.0" iyz="0.0" />
        </inertial>
    </link>
    <link name="link_3">
        <collision>
            <geometry>
                <mesh filename="package://abb_irb1300_support/meshes/collision/link_3.STL" />
            </geometry>
        </collision>
        <visual>
            <geometry>
                <mesh filename="package://abb_irb1300_support/meshes/visual/link_3.STL" />
            </geometry>
            <material name="">
                <color rgba="0.3450980 0.3647059 0.3686275 1" />
            </material>
        </visual>
        <inertial>
            <mass value="0.1" />
            <origin xyz="0 0 0" rpy="0 0 0" />
            <inertia ixx="0.03" iyy="0.03" izz="0.03" ixy="0.0" ixz="0.0" iyz="0.0" />
        </inertial>
    </link>
    <link name="link_4">
        <collision>
            <geometry>
                <mesh filename="package://abb_irb1300_support/meshes/collision/link_4.STL" />
            </geometry>
        </collision>
        <visual>
            <geometry>
                <mesh filename="package://abb_irb1300_support/meshes/visual/link_4.STL" />
            </geometry>
            <material name="">
                <color rgba="0.7725490 0.7803922 0.7686275 1" />
            </material>
        </visual>
        <inertial>
            <mass value="0.1" />
            <origin xyz="0 0 0" rpy="0 0 0" />
            <inertia ixx="0.03" iyy="0.03" izz="0.03" ixy="0.0" ixz="0.0" iyz="0.0" />
        </inertial>
    </link>
    <link name="link_5">
        <collision>
            <geometry>
                <mesh filename="package://abb_irb1300_support/meshes/collision/link_5.STL" />
            </geometry>
        </collision>
        <visual>
            <geometry>
                <mesh filename="package://abb_irb1300_support/meshes/visual/link_5.STL" />
            </geometry>
            <material name="">
                <color rgba="0.7725490 0.7803922 0.7686275 1" />
            </material>
        </visual>
        <inertial>
            <mass value="0.1" />
            <origin xyz="0 0 0" rpy="0 0 0" />
            <inertia ixx="0.03" iyy="0.03" izz="0.03" ixy="0.0" ixz="0.0" iyz="0.0" />
        </inertial>
    </link>
    <link name="link_6">
        <collision>
            <geometry>
                <mesh filename="package://abb_irb1300_support/meshes/collision/link_6.STL" />
            </geometry>
        </collision>
        <visual>
            <geometry>
                <mesh filename="package://abb_irb1300_support/meshes/visual/link_6.STL" />
            </geometry>
            <material name="">
                <color rgba="0.8392157 0.8352941 0.7921569 1" />
            </material>
        </visual>
        <inertial>
            <mass value="0.1" />
            <origin xyz="0 0 0" rpy="0 0 0" />
            <inertia ixx="0.03" iyy="0.03" izz="0.03" ixy="0.0" ixz="0.0" iyz="0.0" />
        </inertial>
    </link>
    <!-- end of link list -->
    <!-- joint list -->
    <joint name="joint_1" type="revolute">
        <origin rpy="0 0 0" xyz="-0.43218 -0.48436 0.20975" />
        <axis xyz="0 0 1" />
        <parent link="base_link" />
        <child link="link_1" />
        <limit effort="0" lower="-3.141592653589793" upper="3.141592653589793" velocity="3.9269908169872414" />
    </joint>
    <joint name="joint_2" type="revolute">
        <origin rpy="0 0.33992 0" xyz="0.15 0 0.292" />
        <axis xyz="0 1 0" />
        <parent link="link_1" />
        <child link="link_2" />
        <limit effort="0" lower="-1.6580627893946132" upper="2.705260340591211" velocity="3.141592653589793" />
    </joint>
    <joint name="joint_3" type="revolute">
        <origin rpy="0 -0.57698 0" xyz="0 0 0.575" />
        <axis xyz="0 1 0" />
        <parent link="link_2" />
        <child link="link_3" />
        <limit effort="0" lower="-3.6651914291880923" upper="1.2042771838760873" velocity="2.443460952792061" />
    </joint>
    <joint name="joint_4" type="revolute">
        <origin rpy="0.1453 0 0" xyz="0.090805 0 0.04" />
        <axis xyz="1 0 0" />
        <parent link="link_3" />
        <child link="link_4" />
        <limit effort="0" lower="-4.014257279586958" upper="4.014257279586958" velocity="8.726646259971648" />
    </joint>
    <joint name="joint_5" type="revolute">
        <origin rpy="0 0.20514 0" xyz="0.5842 0 0" />
        <axis xyz="0 1 0" />
        <parent link="link_4" />
        <child link="link_5" />
        <limit effort="0" lower="-2.2689280275926285" upper="2.2689280275926285" velocity="7.243116395776467" />
    </joint>
    <joint name="joint_6" type="revolute">
        <origin rpy="1.429 0 0" xyz="0.077932 0 0" />
        <axis xyz="1 0 0" />
        <parent link="link_5" />
        <child link="link_6" />
        <limit effort="0" lower="-6.981317007977318" upper="6.981317007977318" velocity="12.566370614359172" />
    </joint>
    <!-- end of joint list -->
    <!-- ROS-Industrial 'base' frame: base_link to ABB World Coordinates transform -->
    <link name="base" />
    <joint name="base_link-base" type="fixed">
        <origin rpy="0 0 0" xyz="0 0 0" />
        <parent link="base_link" />
        <child link="base" />
    </joint>
    <!-- ROS-Industrial 'flange' frame: attachment point for EEF models -->
    <link name="flange" />
    <joint name="joint_6-flange" type="fixed">
        <origin rpy="0 0 0" xyz="0 0 0" />
        <parent link="link_6" />
        <child link="flange" />
    </joint>
    <!-- ROS-Industrial 'tool0' frame: all-zeros tool frame -->
    <link name="tool0" />
    <joint name="flange-tool0" type="fixed">
        <origin rpy="0 1.5707963267948966 0" xyz="0 0 0" />
        <parent link="flange" />
        <child link="tool0" />
    </joint>
    <transmission name="trans_joint_1">
        <type>transmission_interface/SimpleTransmission</type>
        <joint name="joint_1">
            <hardwareInterface>hardware_interface/EffortJointInterface</hardwareInterface>
        </joint>
        <actuator name="joint_1_motor">
            <hardwareInterface>hardware_interface/EffortJointInterface</hardwareInterface>
            <mechanicalReduction>1</mechanicalReduction>
        </actuator>
    </transmission>
    <transmission name="trans_joint_2">
        <type>transmission_interface/SimpleTransmission</type>
        <joint name="joint_2">
            <hardwareInterface>hardware_interface/EffortJointInterface</hardwareInterface>
        </joint>
        <actuator name="joint_2_motor">
            <hardwareInterface>hardware_interface/EffortJointInterface</hardwareInterface>
            <mechanicalReduction>1</mechanicalReduction>
        </actuator>
    </transmission>
    <transmission name="trans_joint_3">
        <type>transmission_interface/SimpleTransmission</type>
        <joint name="joint_3">
            <hardwareInterface>hardware_interface/EffortJointInterface</hardwareInterface>
        </joint>
        <actuator name="joint_3_motor">
            <hardwareInterface>hardware_interface/EffortJointInterface</hardwareInterface>
            <mechanicalReduction>1</mechanicalReduction>
        </actuator>
    </transmission>
    <transmission name="trans_joint_4">
        <type>transmission_interface/SimpleTransmission</type>
        <joint name="joint_4">
            <hardwareInterface>hardware_interface/EffortJointInterface</hardwareInterface>
        </joint>
        <actuator name="joint_4_motor">
            <hardwareInterface>hardware_interface/EffortJointInterface</hardwareInterface>
            <mechanicalReduction>1</mechanicalReduction>
        </actuator>
    </transmission>
    <transmission name="trans_joint_5">
        <type>transmission_interface/SimpleTransmission</type>
        <joint name="joint_5">
            <hardwareInterface>hardware_interface/EffortJointInterface</hardwareInterface>
        </joint>
        <actuator name="joint_5_motor">
            <hardwareInterface>hardware_interface/EffortJointInterface</hardwareInterface>
            <mechanicalReduction>1</mechanicalReduction>
        </actuator>
    </transmission>
    <transmission name="trans_joint_6">
        <type>transmission_interface/SimpleTransmission</type>
        <joint name="joint_6">
            <hardwareInterface>hardware_interface/EffortJointInterface</hardwareInterface>
        </joint>
        <actuator name="joint_6_motor">
            <hardwareInterface>hardware_interface/EffortJointInterface</hardwareInterface>
            <mechanicalReduction>1</mechanicalReduction>
        </actuator>
    </transmission>
    <gazebo>
        <plugin name="gazebo_ros_control" filename="libgazebo_ros_control.so">
            <robotNamespace>/</robotNamespace>
        </plugin>
    </gazebo>
</robot>

